Workbook
Name IQ_CH: 110000
Name IQ_CQ: 5000
Name IQ_CY: 10000
Name IQ_DAILY: 500000
Name IQ_FH: 100000
Name IQ_FQ: 500
Name IQ_FY: 1000
Name IQ_LTM: 2000
Name IQ_MONTH: 15000
Name IQ_NTM: 6000
Name IQ_WEEK: 50000
Name IQ_YTD: 3000
Name UPDATE: 'Raw Data Trent Ltd'!$E$1
Name UPDATE: #REF!

Sheet Historical IFS Trent Ltd
B2: ="Historical Financial Statements - "&'Raw Data Trent Ltd'!$B$1&"." -> Historical Financial Statements - TRENT LTD.
B3: Years | C3: ='Raw Data Trent Ltd'!B16 -> 42825 | D3: =C3+365 -> 43190 | E3: =D3+365 -> 43555 | F3: =E3+365 -> 43920 | G3: =F3+365 -> 44285 | H3: =G3+365 -> 44650 | I3: =H3+365 -> 45015 | J3: =I3+365 -> 45380 | K3: =J3+365 -> 45745 | L3: =K3+365 -> 46110 | M3: LTM
A5: # | B5: Income Statement
B6: Sales | C6: =IFERROR('Raw Data Trent Ltd'!B17,0) -> 1812.44 | D6: =IFERROR('Raw Data Trent Ltd'!C17,0) -> 2157.46 | E6: =IFERROR('Raw Data Trent Ltd'!D17,0) -> 2630.24 | F6: =IFERROR('Raw Data Trent Ltd'!E17,0) -> 3485.98 | G6: =IFERROR('Raw Data Trent Ltd'!F17,0) -> 2592.96 | H6: =IFERROR('Raw Data Trent Ltd'!G17,0) -> 4498.02 | I6: =IFERROR('Raw Data Trent Ltd'!H17,0) -> 8242.02 | J6: =IFERROR('Raw Data Trent Ltd'!I17,0) -> 12375.11 | ... L6: =IFERROR('Raw Data Trent Ltd'!K17,0) -> 20074.21 | M6: =IFERROR(SUM('Raw Data Trent Ltd'!H42:K42),0) -> 20074.21
B7: Sales Growth | D7: =(D6/C6)-1 -> 0.19036216 | E7: =(E6/D6)-1 -> 0.21913732 | F7: =(F6/E6)-1 -> 0.32534674 | G7: =(G6/F6)-1 -> -0.25617473 | H7: =(H6/G6)-1 -> 0.73470474 | I7: =(I6/H6)-1 -> 0.83236624 | J7: =(J6/I6)-1 -> 0.50146566 | K7: =(K6/J6)-1 -> 0.38460264 | ... M7: =(M6/L6)-1 -> 0
B9: COGS | C9: =IFERROR(SUM('Raw Data Trent Ltd'!B18,'Raw Data Trent Ltd'!B20:B22)-1*'Raw Data Trent Ltd'!B19,0) -> 1209.27 | D9: =IFERROR(SUM('Raw Data Trent Ltd'!C18,'Raw Data Trent Ltd'!C20:C22)-1*'Raw Data Trent Ltd'!C19,0) -> 1408.06 | E9: =IFERROR(SUM('Raw Data Trent Ltd'!D18,'Raw Data Trent Ltd'!D20:D22)-1*'Raw Data Trent Ltd'!D19,0) -> 1781.6 | F9: =IFERROR(SUM('Raw Data Trent Ltd'!E18,'Raw Data Trent Ltd'!E20:E22)-1*'Raw Data Trent Ltd'!E19,0) -> 2406.91 | G9: =IFERROR(SUM('Raw Data Trent Ltd'!F18,'Raw Data Trent Ltd'!F20:F22)-1*'Raw Data Trent Ltd'!F19,0) -> 1978.81 | H9: =IFERROR(SUM('Raw Data Trent Ltd'!G18,'Raw Data Trent Ltd'!G20:G22)-1*'Raw Data Trent Ltd'!G19,0) -> 3083.49 | I9: =IFERROR(SUM('Raw Data Trent Ltd'!H18,'Raw Data Trent Ltd'!H20:H22)-1*'Raw Data Trent Ltd'!H19,0) -> 5735.08 | J9: =IFERROR(SUM('Raw Data Trent Ltd'!I18,'Raw Data Trent Ltd'!I20:I22)-1*'Raw Data Trent Ltd'!I19,0) -> 8494.38 | ... L9: =IFERROR(SUM('Raw Data Trent Ltd'!K18,'Raw Data Trent Ltd'!K20:K22)-1*'Raw Data Trent Ltd'!K19,0) -> 12620.2 | M9: =IFERROR(SUM('Raw Data Trent Ltd'!H43:K43),0) -> 16418
B10: COGS % Sales | C10: =C9/C6 -> 0.66720554 | D10: =D9/D6 -> 0.65264709 | E10: =E9/E6 -> 0.67735264 | F10: =F9/F6 -> 0.69045433 | G10: =G9/G6 -> 0.76314714 | H10: =H9/H6 -> 0.68552163 | I10: =I9/I6 -> 0.69583427 | J10: =J9/J6 -> 0.68640844 | ... M10: =M9/M6 -> 0.81786531
B12: Gross Profit | C12: =C6-C9 -> 603.17 | D12: =D6-D9 -> 749.4 | E12: =E6-E9 -> 848.64 | F12: =F6-F9 -> 1079.07 | G12: =G6-G9 -> 614.15 | H12: =H6-H9 -> 1414.53 | I12: =I6-I9 -> 2506.94 | J12: =J6-J9 -> 3880.73 | ... M12: =M6-M9 -> 3656.21
B13: GP % Sales | C13: =C12/C6 -> 0.33279446 | D13: =D12/D6 -> 0.34735291 | E13: =E12/E6 -> 0.32264736 | F13: =F12/F6 -> 0.30954567 | G13: =G12/G6 -> 0.23685286 | H13: =H12/H6 -> 0.31447837 | I13: =I12/I6 -> 0.30416573 | J13: =J12/J6 -> 0.31359156 | ... M13: =M12/M6 -> 0.18213469
B15: Selling & General Expenses | C15: =IFERROR(SUM('Raw Data Trent Ltd'!B23:B24),0) -> 469.64 | D15: =IFERROR(SUM('Raw Data Trent Ltd'!C23:C24),0) -> 540.9 | E15: =IFERROR(SUM('Raw Data Trent Ltd'!D23:D24),0) -> 608 | F15: =IFERROR(SUM('Raw Data Trent Ltd'!E23:E24),0) -> 550.1 | G15: =IFERROR(SUM('Raw Data Trent Ltd'!F23:F24),0) -> 500.28 | H15: =IFERROR(SUM('Raw Data Trent Ltd'!G23:G24),0) -> 819.81 | I15: =IFERROR(SUM('Raw Data Trent Ltd'!H23:H24),0) -> 1392.79 | J15: =IFERROR(SUM('Raw Data Trent Ltd'!I23:I24),0) -> 1910.04 | ... L15: =IFERROR(SUM('Raw Data Trent Ltd'!K23:K24),0) -> 3780.62
B16: S&G Exp % Sales | C16: =C15/C6 -> 0.2591203 | D16: =D15/D6 -> 0.25071148 | E16: =E15/E6 -> 0.23115761 | F16: =F15/F6 -> 0.15780354 | G16: =G15/G6 -> 0.1929378 | H16: =H15/H6 -> 0.18226019 | I16: =I15/I6 -> 0.16898649 | J16: =J15/J6 -> 0.15434529 | ... L16: =L15/L6 -> 0.18833219
B18: EBITDA | C18: =C12-C15 -> 133.53 | D18: =D12-D15 -> 208.5 | E18: =E12-E15 -> 240.64 | F18: =F12-F15 -> 528.97 | G18: =G12-G15 -> 113.87 | H18: =H12-H15 -> 594.72 | I18: =I12-I15 -> 1114.15 | J18: =J12-J15 -> 1970.69 | ... L18: =L12-L15 -> 3673.39 | M18: =IFERROR(SUM('Raw Data Trent Ltd'!H51:K51),0) -> 3764.34
B19: EBITDA % Sales | C19: =C18/C6 -> 0.073674163 | D19: =D18/D6 -> 0.096641421 | E19: =E18/E6 -> 0.09148975 | F19: =F18/F6 -> 0.15174212 | G19: =G18/G6 -> 0.043915062 | H19: =H18/H6 -> 0.13221818 | I19: =I18/I6 -> 0.13517924 | J19: =J18/J6 -> 0.15924626 | ... M19: =M18/M6 -> 0.1875212
B21: Interest | C21: =IFERROR('Raw Data Trent Ltd'!B27,0) -> 45.55 | D21: =IFERROR('Raw Data Trent Ltd'!C27,0) -> 43.78 | E21: =IFERROR('Raw Data Trent Ltd'!D27,0) -> 50.64 | F21: =IFERROR('Raw Data Trent Ltd'!E27,0) -> 263.37 | G21: =IFERROR('Raw Data Trent Ltd'!F27,0) -> 260.79 | H21: =IFERROR('Raw Data Trent Ltd'!G27,0) -> 324.84 | I21: =IFERROR('Raw Data Trent Ltd'!H27,0) -> 408.99 | J21: =IFERROR('Raw Data Trent Ltd'!I27,0) -> 367.66 | ... L21: =IFERROR('Raw Data Trent Ltd'!K27,0) -> 168.35 | M21: =IFERROR(SUM('Raw Data Trent Ltd'!H46:K46),0) -> 168.35
B22: Interest % Sales | C22: =C21/C6 -> 0.025131866 | D22: =D21/D6 -> 0.020292381 | E22: =E21/E6 -> 0.019252996 | F22: =F21/F6 -> 0.075551208 | G22: =G21/G6 -> 0.10057618 | H22: =H21/H6 -> 0.072218443 | I22: =I21/I6 -> 0.049622544 | J22: =J21/J6 -> 0.029709635 | ... M22: =M21/M6 -> 0.0083863823
B24: Depriciation | C24: =IFERROR('Raw Data Trent Ltd'!B26,0) -> 41.29 | D24: =IFERROR('Raw Data Trent Ltd'!C26,0) -> 45.53 | E24: =IFERROR('Raw Data Trent Ltd'!D26,0) -> 51.67 | F24: =IFERROR('Raw Data Trent Ltd'!E26,0) -> 247.24 | G24: =IFERROR('Raw Data Trent Ltd'!F26,0) -> 257.3 | H24: =IFERROR('Raw Data Trent Ltd'!G26,0) -> 310.82 | I24: =IFERROR('Raw Data Trent Ltd'!H26,0) -> 493.69 | J24: =IFERROR('Raw Data Trent Ltd'!I26,0) -> 671.11 | ... L24: =IFERROR('Raw Data Trent Ltd'!K26,0) -> 1361.19 | M24: =IFERROR(SUM('Raw Data Trent Ltd'!H45:K45),0) -> 1361.19
B25: Deprication % Sales | C25: =C24/C6 -> 0.022781444 | D25: =D24/D6 -> 0.02110352 | E25: =E24/E6 -> 0.019644595 | F25: =F24/F6 -> 0.070924102 | G25: =G24/G6 -> 0.099230223 | H25: =H24/H6 -> 0.069101516 | I25: =I24/I6 -> 0.059899151 | J25: =J24/J6 -> 0.054230629 | ... M25: =M24/M6 -> 0.067807899
B27: Earnings before Tax | C27: =IFERROR(C18-SUM(C21,C24),0) -> 46.69 | D27: =IFERROR(D18-SUM(D21,D24),0) -> 119.19 | E27: =IFERROR(E18-SUM(E21,E24),0) -> 138.33 | F27: =IFERROR(F18-SUM(F21,F24),0) -> 18.36 | G27: =IFERROR(G18-SUM(G21,G24),0) -> -404.22 | H27: =IFERROR(H18-SUM(H21,H24),0) -> -40.94 | I27: =IFERROR(I18-SUM(I21,I24),0) -> 211.47 | J27: =IFERROR(J18-SUM(J21,J24),0) -> 931.92 | ... M27: =IFERROR(M18-SUM(M21,M24),0) -> 2234.8
B28: EBT % Sales | C28: =C27/C6 -> 0.025760853 | D28: =D27/D6 -> 0.05524552 | E28: =E27/E6 -> 0.052592159 | F28: =F27/F6 -> 0.0052668116 | G28: =G27/G6 -> -0.15589134 | H28: =H27/H6 -> -0.0091017826 | I28: =I27/I6 -> 0.025657545 | J28: =J27/J6 -> 0.075305997 | ... M28: =M27/M6 -> 0.11132692
B30: Tax | C30: =IFERROR('Raw Data Trent Ltd'!B29,0) -> 43.05 | D30: =IFERROR('Raw Data Trent Ltd'!C29,0) -> 59.62 | E30: =IFERROR('Raw Data Trent Ltd'!D29,0) -> 73.61 | F30: =IFERROR('Raw Data Trent Ltd'!E29,0) -> 59.01 | G30: =IFERROR('Raw Data Trent Ltd'!F29,0) -> -23.69 | H30: =IFERROR('Raw Data Trent Ltd'!G29,0) -> 76.62 | I30: =IFERROR('Raw Data Trent Ltd'!H29,0) -> 158.44 | J30: =IFERROR('Raw Data Trent Ltd'!I29,0) -> 443.37 | ... L30: =IFERROR('Raw Data Trent Ltd'!K29,0) -> 515.15 | M30: =IFERROR(SUM('Raw Data Trent Ltd'!H48:K48),0) -> 515.15
B31: Effective Tax Rate | C31: =C30/C27 -> 0.92203898 | D31: =D30/D27 -> 0.50020975 | E31: =E30/E27 -> 0.5321333 | F31: =F30/F27 -> 3.2140523 | G31: =G30/G27 -> 0.058606699 | H31: =H30/H27 -> -1.8715193 | I31: =I30/I27 -> 0.74923157 | J31: =J30/J27 -> 0.47575972 | ... M31: =M30/M27 -> 0.2305128
B33: Net Profit | C33: =IFERROR(C27-C30,0) -> 3.64 | D33: =IFERROR(D27-D30,0) -> 59.57 | E33: =IFERROR(E27-E30,0) -> 64.72 | F33: =IFERROR(F27-F30,0) -> -40.65 | G33: =IFERROR(G27-G30,0) -> -380.53 | H33: =IFERROR(H27-H30,0) -> -117.56 | I33: =IFERROR(I27-I30,0) -> 53.03 | J33: =IFERROR(J27-J30,0) -> 488.55 | ... M33: =IFERROR(M27-M30,0) -> 1719.65
B34: Net Margin | C34: =C33/C6 -> 0.0020083423 | D34: =D33/D6 -> 0.027611172 | E34: =E33/E6 -> 0.02460612 | F34: =F33/F6 -> -0.011660996 | G34: =G33/G6 -> -0.14675506 | H34: =H33/H6 -> -0.026135944 | I34: =I33/I6 -> 0.0064341023 | J34: =J33/J6 -> 0.039478437 | ... M34: =M33/M6 -> 0.085664641
B36: No of Equity Share | C36: =IFERROR('Raw Data Trent Ltd'!B93,0) -> 33.23 | D36: =IFERROR('Raw Data Trent Ltd'!C93,0) -> 33.23 | E36: =IFERROR('Raw Data Trent Ltd'!D93,0) -> 33.23 | F36: =IFERROR('Raw Data Trent Ltd'!E93,0) -> 35.55 | G36: =IFERROR('Raw Data Trent Ltd'!F93,0) -> 35.55 | H36: =IFERROR('Raw Data Trent Ltd'!G93,0) -> 35.55 | I36: =IFERROR('Raw Data Trent Ltd'!H93,0) -> 35.55 | J36: =IFERROR('Raw Data Trent Ltd'!I93,0) -> 35.55 | ... M36: =IFERROR('Raw Data Trent Ltd'!L93,0) -> 0
B38: EPS | C38: =C33/C36 -> 0.10953957 | D38: =D33/D36 -> 1.7926572 | E38: =E33/E36 -> 1.9476377 | F38: =F33/F36 -> -1.1434599 | G38: =G33/G36 -> -10.704079 | H38: =H33/H36 -> -3.3068917 | I38: =I33/I36 -> 1.4917018 | J38: =J33/J36 -> 13.742616 | ... L38: =L33/L36 -> 45.814346 | M38: =IFERROR(M33/M36,0) -> 0
B39: EPS Growth % | D39: =(D38/C38)-1 -> 15.365385 | E39: =(E38/D38)-1 -> 0.086452913 | F39: =(F38/E38)-1 -> -1.5871009 | G39: =(G38/F38)-1 -> 8.3611316 | H39: =(H38/G38)-1 -> -0.69106247 | I39: =(I38/H38)-1 -> -1.4510888 | J39: =(J38/I38)-1 -> 8.2127098 | K39: =(K38/J38)-1 -> 1.5163238 | ... M39: =(M38/L38)-1 -> -1
B41: Dividend per Share | C41: =IFERROR('Raw Data Trent Ltd'!B31/C36,0) -> 1 | D41: =IFERROR('Raw Data Trent Ltd'!C31/D36,0) -> 1.1498646 | E41: =IFERROR('Raw Data Trent Ltd'!D31/E36,0) -> 1.3000301 | F41: =IFERROR('Raw Data Trent Ltd'!E31/F36,0) -> 1 | G41: =IFERROR('Raw Data Trent Ltd'!F31/G36,0) -> 0.6 | H41: =IFERROR('Raw Data Trent Ltd'!G31/H36,0) -> 1.7001406 | I41: =IFERROR('Raw Data Trent Ltd'!H31/I36,0) -> 2.2 | J41: =IFERROR('Raw Data Trent Ltd'!I31/J36,0) -> 3.2 | ... M41: =IFERROR('Raw Data Trent Ltd'!L31/M36,0) -> 0
B42: Divident Payout Ratio % | C42: =IFERROR(C41/C38,0) -> 9.1291209 | D42: =IFERROR(D41/D38,0) -> 0.64143025 | E42: =IFERROR(E41/E38,0) -> 0.66749073 | F42: =IFERROR(F41/F38,0) -> -0.87453875 | G42: =IFERROR(G41/G38,0) -> -0.056053399 | H42: =IFERROR(H41/H38,0) -> -0.51412045 | I42: =IFERROR(I41/I38,0) -> 1.4748256 | J42: =IFERROR(J41/J38,0) -> 0.23285232 | ... M42: =IFERROR(M41/M38,0) -> 0
B44: Retained Earnings | C44: =IFERROR(IF(C38>C41,1-C42,0),0) -> 0 | D44: =IFERROR(IF(D38>D41,1-D42,0),0) -> 0.35856975 | E44: =IFERROR(IF(E38>E41,1-E42,0),0) -> 0.33250927 | F44: =IFERROR(IF(F38>F41,1-F42,0),0) -> 0 | G44: =IFERROR(IF(G38>G41,1-G42,0),0) -> 0 | H44: =IFERROR(IF(H38>H41,1-H42,0),0) -> 0 | I44: =IFERROR(IF(I38>I41,1-I42,0),0) -> 0 | J44: =IFERROR(IF(J38>J41,1-J42,0),0) -> 0.76714768 | ... M44: =IFERROR(IF(M38>M41,1-M42,0),0) -> 0
A46: # | B46: Balace Sheet
B47: Equity Share Capital | C47: =IFERROR('Raw Data Trent Ltd'!B57,0) -> 33.23 | D47: =IFERROR('Raw Data Trent Ltd'!C57,0) -> 33.23 | E47: =IFERROR('Raw Data Trent Ltd'!D57,0) -> 33.23 | F47: =IFERROR('Raw Data Trent Ltd'!E57,0) -> 35.55 | G47: =IFERROR('Raw Data Trent Ltd'!F57,0) -> 35.55 | H47: =IFERROR('Raw Data Trent Ltd'!G57,0) -> 35.55 | I47: =IFERROR('Raw Data Trent Ltd'!H57,0) -> 35.55 | J47: =IFERROR('Raw Data Trent Ltd'!I57,0) -> 35.55 | ... L47: =IFERROR('Raw Data Trent Ltd'!K57,0) -> 35.55
B48: Reserves | C48: =IFERROR('Raw Data Trent Ltd'!B58,0) -> 1514.46 | D48: =IFERROR('Raw Data Trent Ltd'!C58,0) -> 1562.14 | E48: =IFERROR('Raw Data Trent Ltd'!D58,0) -> 1613.28 | F48: =IFERROR('Raw Data Trent Ltd'!E58,0) -> 2352.22 | G48: =IFERROR('Raw Data Trent Ltd'!F58,0) -> 2277.48 | H48: =IFERROR('Raw Data Trent Ltd'!G58,0) -> 2328.45 | I48: =IFERROR('Raw Data Trent Ltd'!H58,0) -> 2559.94 | J48: =IFERROR('Raw Data Trent Ltd'!I58,0) -> 4032.19 | ... L48: =IFERROR('Raw Data Trent Ltd'!K58,0) -> 6949.13
B49: Borrowings | C49: =IFERROR('Raw Data Trent Ltd'!B59,0) -> 391.74 | D49: =IFERROR('Raw Data Trent Ltd'!C59,0) -> 391.43 | E49: =IFERROR('Raw Data Trent Ltd'!D59,0) -> 494.14 | F49: =IFERROR('Raw Data Trent Ltd'!E59,0) -> 299.74 | G49: =IFERROR('Raw Data Trent Ltd'!F59,0) -> 2963.63 | H49: =IFERROR('Raw Data Trent Ltd'!G59,0) -> 4725.36 | I49: =IFERROR('Raw Data Trent Ltd'!H59,0) -> 4464.14 | J49: =IFERROR('Raw Data Trent Ltd'!I59,0) -> 1752.99 | ... L49: =IFERROR('Raw Data Trent Ltd'!K59,0) -> 2561.25
B50: Other Liabilities | C50: =IFERROR('Raw Data Trent Ltd'!B60,0) -> 282.82 | D50: =IFERROR('Raw Data Trent Ltd'!C60,0) -> 349.06 | E50: =IFERROR('Raw Data Trent Ltd'!D60,0) -> 418.11 | F50: =IFERROR('Raw Data Trent Ltd'!E60,0) -> 2819.17 | G50: =IFERROR('Raw Data Trent Ltd'!F60,0) -> 447.07 | H50: =IFERROR('Raw Data Trent Ltd'!G60,0) -> 636.66 | I50: =IFERROR('Raw Data Trent Ltd'!H60,0) -> 1021.9 | J50: =IFERROR('Raw Data Trent Ltd'!I60,0) -> 1341.02 | ... L50: =IFERROR('Raw Data Trent Ltd'!K60,0) -> 2182.65
B51: Total Liablity | C51: =SUM(C47:C50) -> 2222.25 | D51: =SUM(D47:D50) -> 2335.86 | E51: =SUM(E47:E50) -> 2558.76 | F51: =SUM(F47:F50) -> 5506.68 | G51: =SUM(G47:G50) -> 5723.73 | H51: =SUM(H47:H50) -> 7726.02 | I51: =SUM(I47:I50) -> 8081.53 | J51: =SUM(J47:J50) -> 7161.75 | ... L51: =SUM(L47:L50) -> 11728.58
B53: Fixed Asset Net Block | C53: =IFERROR('Raw Data Trent Ltd'!B62,0) -> 548.71 | D53: =IFERROR('Raw Data Trent Ltd'!C62,0) -> 612.53 | E53: =IFERROR('Raw Data Trent Ltd'!D62,0) -> 662.18 | F53: =IFERROR('Raw Data Trent Ltd'!E62,0) -> 2738.43 | G53: =IFERROR('Raw Data Trent Ltd'!F62,0) -> 3053.82 | H53: =IFERROR('Raw Data Trent Ltd'!G62,0) -> 4686.71 | I53: =IFERROR('Raw Data Trent Ltd'!H62,0) -> 4526.95 | J53: =IFERROR('Raw Data Trent Ltd'!I62,0) -> 2449.92 | ... L53: =IFERROR('Raw Data Trent Ltd'!K62,0) -> 5518.74
B54: Capital Work in Progress | C54: =IFERROR('Raw Data Trent Ltd'!B63,0) -> 5.48 | D54: =IFERROR('Raw Data Trent Ltd'!C63,0) -> 9.59 | E54: =IFERROR('Raw Data Trent Ltd'!D63,0) -> 87.18 | F54: =IFERROR('Raw Data Trent Ltd'!E63,0) -> 23.32 | G54: =IFERROR('Raw Data Trent Ltd'!F63,0) -> 107.98 | H54: =IFERROR('Raw Data Trent Ltd'!G63,0) -> 104.72 | I54: =IFERROR('Raw Data Trent Ltd'!H63,0) -> 101.72 | J54: =IFERROR('Raw Data Trent Ltd'!I63,0) -> 223.78 | ... L54: =IFERROR('Raw Data Trent Ltd'!K63,0) -> 253.99
B55: Investments | C55: =IFERROR('Raw Data Trent Ltd'!B64,0) -> 1079.96 | D55: =IFERROR('Raw Data Trent Ltd'!C64,0) -> 1022.88 | E55: =IFERROR('Raw Data Trent Ltd'!D64,0) -> 882.83 | F55: =IFERROR('Raw Data Trent Ltd'!E64,0) -> 1514.78 | G55: =IFERROR('Raw Data Trent Ltd'!F64,0) -> 1487.29 | H55: =IFERROR('Raw Data Trent Ltd'!G64,0) -> 1283.72 | I55: =IFERROR('Raw Data Trent Ltd'!H64,0) -> 1109.87 | J55: =IFERROR('Raw Data Trent Ltd'!I64,0) -> 1416.03 | ... L55: =IFERROR('Raw Data Trent Ltd'!K64,0) -> 1384.91
B56: Other Assets | C56: ='Raw Data Trent Ltd'!B75 -> 242.54 | D56: ='Raw Data Trent Ltd'!C75 -> 298.18 | E56: ='Raw Data Trent Ltd'!D75 -> 358.79 | F56: ='Raw Data Trent Ltd'!E75 -> 543.81 | G56: ='Raw Data Trent Ltd'!F75 -> 544.01 | H56: ='Raw Data Trent Ltd'!G75 -> 678.86 | I56: ='Raw Data Trent Ltd'!H75 -> 861.14 | J56: ='Raw Data Trent Ltd'!I75 -> 1109.99 | ... L56: ='Raw Data Trent Ltd'!K75 -> 1947.79
B57: Total Non Current Assets | C57: =IFERROR(SUM(C53:C56),0) -> 1876.69 | D57: =IFERROR(SUM(D53:D56),0) -> 1943.18 | E57: =IFERROR(SUM(E53:E56),0) -> 1990.98 | F57: =IFERROR(SUM(F53:F56),0) -> 4820.34 | G57: =IFERROR(SUM(G53:G56),0) -> 5193.1 | H57: =IFERROR(SUM(H53:H56),0) -> 6754.01 | I57: =IFERROR(SUM(I53:I56),0) -> 6599.68 | J57: =IFERROR(SUM(J53:J56),0) -> 5199.72 | ... L57: =IFERROR(SUM(L53:L56),0) -> 9105.43
...

Sheet CommonSize Statement Trent Ltd 
B2: ="Common Size Income Statement"&" "&"-"&" "&'Raw Data Trent Ltd'!B1 -> Common Size Income Statement - TRENT LTD
B3: Particulars | C3: ='Raw Data Trent Ltd'!$B$16 -> 42825 | D3: =C3+365 -> 43190 | E3: =D3+365 -> 43555 | F3: =E3+365 -> 43920 | G3: =F3+365 -> 44285 | H3: =G3+365 -> 44650 | I3: =H3+365 -> 45015 | J3: =I3+365 -> 45380 | K3: =J3+365 -> 45745 | L3: =K3+365 -> 46110
B4: ='Raw Data Trent Ltd'!A17 -> Sales | C4: ='Raw Data Trent Ltd'!B17/'Raw Data Trent Ltd'!B$17 -> 1 | D4: ='Raw Data Trent Ltd'!C17/'Raw Data Trent Ltd'!C$17 -> 1 | E4: ='Raw Data Trent Ltd'!D17/'Raw Data Trent Ltd'!D$17 -> 1 | F4: ='Raw Data Trent Ltd'!E17/'Raw Data Trent Ltd'!E$17 -> 1 | G4: ='Raw Data Trent Ltd'!F17/'Raw Data Trent Ltd'!F$17 -> 1 | H4: ='Raw Data Trent Ltd'!G17/'Raw Data Trent Ltd'!G$17 -> 1 | I4: ='Raw Data Trent Ltd'!H17/'Raw Data Trent Ltd'!H$17 -> 1 | J4: ='Raw Data Trent Ltd'!I17/'Raw Data Trent Ltd'!I$17 -> 1 | ... L4: ='Raw Data Trent Ltd'!K17/'Raw Data Trent Ltd'!K$17 -> 1
B5: ='Raw Data Trent Ltd'!A18 -> Raw Material Cost | C5: ='Raw Data Trent Ltd'!B18/'Raw Data Trent Ltd'!B$17 -> 0.50275871 | D5: ='Raw Data Trent Ltd'!C18/'Raw Data Trent Ltd'!C$17 -> 0.49596285 | E5: ='Raw Data Trent Ltd'!D18/'Raw Data Trent Ltd'!D$17 -> 0.55495696 | F5: ='Raw Data Trent Ltd'!E18/'Raw Data Trent Ltd'!E$17 -> 0.55985404 | G5: ='Raw Data Trent Ltd'!F18/'Raw Data Trent Ltd'!F$17 -> 0.52898618 | H5: ='Raw Data Trent Ltd'!G18/'Raw Data Trent Ltd'!G$17 -> 0.64925901 | I5: ='Raw Data Trent Ltd'!H18/'Raw Data Trent Ltd'!H$17 -> 0.63225399 | J5: ='Raw Data Trent Ltd'!I18/'Raw Data Trent Ltd'!I$17 -> 0.57563933 | ... L5: ='Raw Data Trent Ltd'!K18/'Raw Data Trent Ltd'!K$17 -> 0.57271942
B6: ='Raw Data Trent Ltd'!A19 -> Change in Inventory | C6: ='Raw Data Trent Ltd'!B19/'Raw Data Trent Ltd'!B$17 -> 0.016475028 | D6: ='Raw Data Trent Ltd'!C19/'Raw Data Trent Ltd'!C$17 -> 0.017849694 | E6: ='Raw Data Trent Ltd'!D19/'Raw Data Trent Ltd'!D$17 -> 0.056356074 | F6: ='Raw Data Trent Ltd'!E19/'Raw Data Trent Ltd'!E$17 -> 0.020048882 | G6: ='Raw Data Trent Ltd'!F19/'Raw Data Trent Ltd'!F$17 -> -0.062615698 | H6: ='Raw Data Trent Ltd'!G19/'Raw Data Trent Ltd'!G$17 -> 0.097562928 | I6: ='Raw Data Trent Ltd'!H19/'Raw Data Trent Ltd'!H$17 -> 0.059610387 | J6: ='Raw Data Trent Ltd'!I19/'Raw Data Trent Ltd'!I$17 -> 0.013309781 | ... L6: ='Raw Data Trent Ltd'!K19/'Raw Data Trent Ltd'!K$17 -> 0.011566084
B7: ='Raw Data Trent Ltd'!A20 -> Power and Fuel | C7: ='Raw Data Trent Ltd'!B20/'Raw Data Trent Ltd'!B$17 -> 0.02829335 | D7: ='Raw Data Trent Ltd'!C20/'Raw Data Trent Ltd'!C$17 -> 0.024450048 | E7: ='Raw Data Trent Ltd'!D20/'Raw Data Trent Ltd'!D$17 -> 0.022499848 | F7: ='Raw Data Trent Ltd'!E20/'Raw Data Trent Ltd'!E$17 -> 0.019116576 | G7: ='Raw Data Trent Ltd'!F20/'Raw Data Trent Ltd'!F$17 -> 0.019055442 | H7: ='Raw Data Trent Ltd'!G20/'Raw Data Trent Ltd'!G$17 -> 0.015982588 | I7: ='Raw Data Trent Ltd'!H20/'Raw Data Trent Ltd'!H$17 -> 0.017505417 | J7: ='Raw Data Trent Ltd'!I20/'Raw Data Trent Ltd'!I$17 -> 0.018517815 | ... L7: ='Raw Data Trent Ltd'!K20/'Raw Data Trent Ltd'!K$17 -> 0
B8: ='Raw Data Trent Ltd'!A21 -> Other Mfr. Exp | C8: ='Raw Data Trent Ltd'!B21/'Raw Data Trent Ltd'!B$17 -> 0.04519322 | D8: ='Raw Data Trent Ltd'!C21/'Raw Data Trent Ltd'!C$17 -> 0.042077258 | E8: ='Raw Data Trent Ltd'!D21/'Raw Data Trent Ltd'!D$17 -> 0.046417817 | F8: ='Raw Data Trent Ltd'!E21/'Raw Data Trent Ltd'!E$17 -> 0.027972048 | G8: ='Raw Data Trent Ltd'!F21/'Raw Data Trent Ltd'!F$17 -> 0.035480686 | H8: ='Raw Data Trent Ltd'!G21/'Raw Data Trent Ltd'!G$17 -> 0.02826577 | I8: ='Raw Data Trent Ltd'!H21/'Raw Data Trent Ltd'!H$17 -> 0.025720636 | J8: ='Raw Data Trent Ltd'!I21/'Raw Data Trent Ltd'!I$17 -> 0.02138082 | ... L8: ='Raw Data Trent Ltd'!K21/'Raw Data Trent Ltd'!K$17 -> 0
B9: ='Raw Data Trent Ltd'!A22 -> Employee Cost | C9: ='Raw Data Trent Ltd'!B22/'Raw Data Trent Ltd'!B$17 -> 0.10743528 | D9: ='Raw Data Trent Ltd'!C22/'Raw Data Trent Ltd'!C$17 -> 0.10800664 | E9: ='Raw Data Trent Ltd'!D22/'Raw Data Trent Ltd'!D$17 -> 0.10983408 | F9: ='Raw Data Trent Ltd'!E22/'Raw Data Trent Ltd'!E$17 -> 0.10356055 | G9: ='Raw Data Trent Ltd'!F22/'Raw Data Trent Ltd'!F$17 -> 0.11700913 | H9: ='Raw Data Trent Ltd'!G22/'Raw Data Trent Ltd'!G$17 -> 0.089577192 | I9: ='Raw Data Trent Ltd'!H22/'Raw Data Trent Ltd'!H$17 -> 0.07996462 | J9: ='Raw Data Trent Ltd'!I22/'Raw Data Trent Ltd'!I$17 -> 0.084180262 | ... L9: ='Raw Data Trent Ltd'!K22/'Raw Data Trent Ltd'!K$17 -> 0.067523952
B10: ='Raw Data Trent Ltd'!A23 -> Selling and admin | C10: ='Raw Data Trent Ltd'!B23/'Raw Data Trent Ltd'!B$17 -> 0.22459778 | D10: ='Raw Data Trent Ltd'!C23/'Raw Data Trent Ltd'!C$17 -> 0.20886135 | E10: ='Raw Data Trent Ltd'!D23/'Raw Data Trent Ltd'!D$17 -> 0.19557531 | F10: ='Raw Data Trent Ltd'!E23/'Raw Data Trent Ltd'!E$17 -> 0.12530766 | G10: ='Raw Data Trent Ltd'!F23/'Raw Data Trent Ltd'!F$17 -> 0.14061922 | H10: ='Raw Data Trent Ltd'!G23/'Raw Data Trent Ltd'!G$17 -> 0.1567423 | I10: ='Raw Data Trent Ltd'!H23/'Raw Data Trent Ltd'!H$17 -> 0.15196881 | J10: ='Raw Data Trent Ltd'!I23/'Raw Data Trent Ltd'!I$17 -> 0.13814423 | ... L10: ='Raw Data Trent Ltd'!K23/'Raw Data Trent Ltd'!K$17 -> 0.077907923
B11: ='Raw Data Trent Ltd'!A24 -> Other Expenses | C11: ='Raw Data Trent Ltd'!B24/'Raw Data Trent Ltd'!B$17 -> 0.034522522 | D11: ='Raw Data Trent Ltd'!C24/'Raw Data Trent Ltd'!C$17 -> 0.041850139 | E11: ='Raw Data Trent Ltd'!D24/'Raw Data Trent Ltd'!D$17 -> 0.035582304 | F11: ='Raw Data Trent Ltd'!E24/'Raw Data Trent Ltd'!E$17 -> 0.032495884 | G11: ='Raw Data Trent Ltd'!F24/'Raw Data Trent Ltd'!F$17 -> 0.052318586 | H11: ='Raw Data Trent Ltd'!G24/'Raw Data Trent Ltd'!G$17 -> 0.025517895 | I11: ='Raw Data Trent Ltd'!H24/'Raw Data Trent Ltd'!H$17 -> 0.017017673 | J11: ='Raw Data Trent Ltd'!I24/'Raw Data Trent Ltd'!I$17 -> 0.016201068 | ... L11: ='Raw Data Trent Ltd'!K24/'Raw Data Trent Ltd'!K$17 -> 0.11042427
B12: ='Raw Data Trent Ltd'!A25 -> Other Income | C12: ='Raw Data Trent Ltd'!B25/'Raw Data Trent Ltd'!B$17 -> 0.044862175 | D12: ='Raw Data Trent Ltd'!C25/'Raw Data Trent Ltd'!C$17 -> 0.012732565 | E12: ='Raw Data Trent Ltd'!D25/'Raw Data Trent Ltd'!D$17 -> 0.01145903 | F12: ='Raw Data Trent Ltd'!E25/'Raw Data Trent Ltd'!E$17 -> 0.042062777 | G12: ='Raw Data Trent Ltd'!F25/'Raw Data Trent Ltd'!F$17 -> 0.076900531 | H12: ='Raw Data Trent Ltd'!G25/'Raw Data Trent Ltd'!G$17 -> 0.033828218 | I12: ='Raw Data Trent Ltd'!H25/'Raw Data Trent Ltd'!H$17 -> 0.041324821 | J12: ='Raw Data Trent Ltd'!I25/'Raw Data Trent Ltd'!I$17 -> 0.079911209 | ... L12: ='Raw Data Trent Ltd'!K25/'Raw Data Trent Ltd'!K$17 -> 0.0046143783
B13: ='Raw Data Trent Ltd'!A26 -> Depreciation | C13: ='Raw Data Trent Ltd'!B26/'Raw Data Trent Ltd'!B$17 -> 0.022781444 | D13: ='Raw Data Trent Ltd'!C26/'Raw Data Trent Ltd'!C$17 -> 0.02110352 | E13: ='Raw Data Trent Ltd'!D26/'Raw Data Trent Ltd'!D$17 -> 0.019644595 | F13: ='Raw Data Trent Ltd'!E26/'Raw Data Trent Ltd'!E$17 -> 0.070924102 | G13: ='Raw Data Trent Ltd'!F26/'Raw Data Trent Ltd'!F$17 -> 0.099230223 | H13: ='Raw Data Trent Ltd'!G26/'Raw Data Trent Ltd'!G$17 -> 0.069101516 | I13: ='Raw Data Trent Ltd'!H26/'Raw Data Trent Ltd'!H$17 -> 0.059899151 | J13: ='Raw Data Trent Ltd'!I26/'Raw Data Trent Ltd'!I$17 -> 0.054230629 | ... L13: ='Raw Data Trent Ltd'!K26/'Raw Data Trent Ltd'!K$17 -> 0.067807899
B14: ='Raw Data Trent Ltd'!A27 -> Interest | C14: ='Raw Data Trent Ltd'!B27/'Raw Data Trent Ltd'!B$17 -> 0.025131866 | D14: ='Raw Data Trent Ltd'!C27/'Raw Data Trent Ltd'!C$17 -> 0.020292381 | E14: ='Raw Data Trent Ltd'!D27/'Raw Data Trent Ltd'!D$17 -> 0.019252996 | F14: ='Raw Data Trent Ltd'!E27/'Raw Data Trent Ltd'!E$17 -> 0.075551208 | G14: ='Raw Data Trent Ltd'!F27/'Raw Data Trent Ltd'!F$17 -> 0.10057618 | H14: ='Raw Data Trent Ltd'!G27/'Raw Data Trent Ltd'!G$17 -> 0.072218443 | I14: ='Raw Data Trent Ltd'!H27/'Raw Data Trent Ltd'!H$17 -> 0.049622544 | J14: ='Raw Data Trent Ltd'!I27/'Raw Data Trent Ltd'!I$17 -> 0.029709635 | ... L14: ='Raw Data Trent Ltd'!K27/'Raw Data Trent Ltd'!K$17 -> 0.0083863823
B15: ='Raw Data Trent Ltd'!A28 -> Profit before tax | C15: ='Raw Data Trent Ltd'!B28/'Raw Data Trent Ltd'!B$17 -> 0.070623028 | D15: ='Raw Data Trent Ltd'!C28/'Raw Data Trent Ltd'!C$17 -> 0.067978085 | E15: ='Raw Data Trent Ltd'!D28/'Raw Data Trent Ltd'!D$17 -> 0.064051189 | F15: ='Raw Data Trent Ltd'!E28/'Raw Data Trent Ltd'!E$17 -> 0.047329589 | G15: ='Raw Data Trent Ltd'!F28/'Raw Data Trent Ltd'!F$17 -> -0.078990806 | H15: ='Raw Data Trent Ltd'!G28/'Raw Data Trent Ltd'!G$17 -> 0.024726435 | I15: ='Raw Data Trent Ltd'!H28/'Raw Data Trent Ltd'!H$17 -> 0.066982366 | J15: ='Raw Data Trent Ltd'!I28/'Raw Data Trent Ltd'!I$17 -> 0.15521721 | ... L15: ='Raw Data Trent Ltd'!K28/'Raw Data Trent Ltd'!K$17 -> 0.11141061
... B18: ='Raw Data Trent Ltd'!A31 -> Dividend Amount | C18: ='Raw Data Trent Ltd'!B31/'Raw Data Trent Ltd'!B$17 -> 0.0183344 | D18: ='Raw Data Trent Ltd'!C31/'Raw Data Trent Ltd'!C$17 -> 0.017710641 | E18: ='Raw Data Trent Ltd'!D31/'Raw Data Trent Ltd'!D$17 -> 0.016424357 | F18: ='Raw Data Trent Ltd'!E31/'Raw Data Trent Ltd'!E$17 -> 0.010197993 | G18: ='Raw Data Trent Ltd'!F31/'Raw Data Trent Ltd'!F$17 -> 0.00822612 | H18: ='Raw Data Trent Ltd'!G31/'Raw Data Trent Ltd'!G$17 -> 0.013437023 | I18: ='Raw Data Trent Ltd'!H31/'Raw Data Trent Ltd'!H$17 -> 0.0094891786 | J18: ='Raw Data Trent Ltd'!I31/'Raw Data Trent Ltd'!I$17 -> 0.0091926456 | ... L18: ='Raw Data Trent Ltd'!K31/'Raw Data Trent Ltd'!K$17 -> 0.010625574
B19: ='Raw Data Trent Ltd'!A34 -> EBITDA | C19: ='Raw Data Trent Ltd'!B34/'Raw Data Trent Ltd'!B$17 -> 0.11848668 | D19: ='Raw Data Trent Ltd'!C34/'Raw Data Trent Ltd'!C$17 -> 0.10934154 | E19: ='Raw Data Trent Ltd'!D34/'Raw Data Trent Ltd'!D$17 -> 0.10374719 | F19: ='Raw Data Trent Ltd'!E34/'Raw Data Trent Ltd'!E$17 -> 0.19864428 | G19: ='Raw Data Trent Ltd'!F34/'Raw Data Trent Ltd'!F$17 -> 0.13429825 | H19: ='Raw Data Trent Ltd'!G34/'Raw Data Trent Ltd'!G$17 -> 0.18188225 | I19: ='Raw Data Trent Ltd'!H34/'Raw Data Trent Ltd'!H$17 -> 0.18269186 | J19: ='Raw Data Trent Ltd'!I34/'Raw Data Trent Ltd'!I$17 -> 0.23991221 | ... L19: ='Raw Data Trent Ltd'!K34/'Raw Data Trent Ltd'!K$17 -> 0.1875212
B21: ="Common Size Balance Sheet"&" "&"-"&" "&'Raw Data Trent Ltd'!B1 -> Common Size Balance Sheet - TRENT LTD
B22: Particulars | C22: ='Raw Data Trent Ltd'!$B$16 -> 42825 | D22: =C22+365 -> 43190 | E22: =D22+365 -> 43555 | F22: =E22+365 -> 43920 | G22: =F22+365 -> 44285 | H22: =G22+365 -> 44650 | I22: =H22+365 -> 45015 | J22: =I22+365 -> 45380 | K22: =J22+365 -> 45745 | L22: =K22+365 -> 46110
B23: Total Liablities | C23: ='Raw Data Trent Ltd'!B61/'Raw Data Trent Ltd'!B$61 -> 1 | D23: ='Raw Data Trent Ltd'!C61/'Raw Data Trent Ltd'!C$61 -> 1 | E23: ='Raw Data Trent Ltd'!D61/'Raw Data Trent Ltd'!D$61 -> 1 | F23: ='Raw Data Trent Ltd'!E61/'Raw Data Trent Ltd'!E$61 -> 1 | G23: ='Raw Data Trent Ltd'!F61/'Raw Data Trent Ltd'!F$61 -> 1 | H23: ='Raw Data Trent Ltd'!G61/'Raw Data Trent Ltd'!G$61 -> 1 | I23: ='Raw Data Trent Ltd'!H61/'Raw Data Trent Ltd'!H$61 -> 1 | J23: ='Raw Data Trent Ltd'!I61/'Raw Data Trent Ltd'!I$61 -> 1 | ... L23: ='Raw Data Trent Ltd'!K61/'Raw Data Trent Ltd'!K$61 -> 1
B24: ='Raw Data Trent Ltd'!A57 -> Equity Share Capital | C24: ='Raw Data Trent Ltd'!B57/'Raw Data Trent Ltd'!B$61 -> 0.014953313 | D24: ='Raw Data Trent Ltd'!C57/'Raw Data Trent Ltd'!C$61 -> 0.014226024 | E24: ='Raw Data Trent Ltd'!D57/'Raw Data Trent Ltd'!D$61 -> 0.012986759 | F24: ='Raw Data Trent Ltd'!E57/'Raw Data Trent Ltd'!E$61 -> 0.0064557955 | G24: ='Raw Data Trent Ltd'!F57/'Raw Data Trent Ltd'!F$61 -> 0.0062109848 | H24: ='Raw Data Trent Ltd'!G57/'Raw Data Trent Ltd'!G$61 -> 0.0046013342 | I24: ='Raw Data Trent Ltd'!H57/'Raw Data Trent Ltd'!H$61 -> 0.0043989195 | J24: ='Raw Data Trent Ltd'!I57/'Raw Data Trent Ltd'!I$61 -> 0.0049638706 | ... L24: ='Raw Data Trent Ltd'!K57/'Raw Data Trent Ltd'!K$61 -> 0.0030310575
B25: ='Raw Data Trent Ltd'!A58 -> Reserves | C25: ='Raw Data Trent Ltd'!B58/'Raw Data Trent Ltd'!B$61 -> 0.68149848 | D25: ='Raw Data Trent Ltd'!C58/'Raw Data Trent Ltd'!C$61 -> 0.6687644 | E25: ='Raw Data Trent Ltd'!D58/'Raw Data Trent Ltd'!D$61 -> 0.63049289 | F25: ='Raw Data Trent Ltd'!E58/'Raw Data Trent Ltd'!E$61 -> 0.42715756 | G25: ='Raw Data Trent Ltd'!F58/'Raw Data Trent Ltd'!F$61 -> 0.39790137 | H25: ='Raw Data Trent Ltd'!G58/'Raw Data Trent Ltd'!G$61 -> 0.30137768 | I25: ='Raw Data Trent Ltd'!H58/'Raw Data Trent Ltd'!H$61 -> 0.31676428 | J25: ='Raw Data Trent Ltd'!I58/'Raw Data Trent Ltd'!I$61 -> 0.56301742 | ... L25: ='Raw Data Trent Ltd'!K58/'Raw Data Trent Ltd'!K$61 -> 0.59249543
B26: ='Raw Data Trent Ltd'!A59 -> Borrowings | C26: ='Raw Data Trent Ltd'!B59/'Raw Data Trent Ltd'!B$61 -> 0.1762808 | D26: ='Raw Data Trent Ltd'!C59/'Raw Data Trent Ltd'!C$61 -> 0.16757426 | E26: ='Raw Data Trent Ltd'!D59/'Raw Data Trent Ltd'!D$61 -> 0.19311698 | F26: ='Raw Data Trent Ltd'!E59/'Raw Data Trent Ltd'!E$61 -> 0.054432072 | G26: ='Raw Data Trent Ltd'!F59/'Raw Data Trent Ltd'!F$61 -> 0.51777949 | H26: ='Raw Data Trent Ltd'!G59/'Raw Data Trent Ltd'!G$61 -> 0.61161633 | I26: ='Raw Data Trent Ltd'!H59/'Raw Data Trent Ltd'!H$61 -> 0.55238798 | J26: ='Raw Data Trent Ltd'!I59/'Raw Data Trent Ltd'!I$61 -> 0.24477118 | ... L26: ='Raw Data Trent Ltd'!K59/'Raw Data Trent Ltd'!K$61 -> 0.21837682
B27: ='Raw Data Trent Ltd'!A60 -> Other Liabilities | C27: ='Raw Data Trent Ltd'!B60/'Raw Data Trent Ltd'!B$61 -> 0.12726741 | D27: ='Raw Data Trent Ltd'!C60/'Raw Data Trent Ltd'!C$61 -> 0.14943533 | E27: ='Raw Data Trent Ltd'!D60/'Raw Data Trent Ltd'!D$61 -> 0.16340337 | F27: ='Raw Data Trent Ltd'!E60/'Raw Data Trent Ltd'!E$61 -> 0.51195457 | G27: ='Raw Data Trent Ltd'!F60/'Raw Data Trent Ltd'!F$61 -> 0.078108157 | H27: ='Raw Data Trent Ltd'!G60/'Raw Data Trent Ltd'!G$61 -> 0.082404653 | I27: ='Raw Data Trent Ltd'!H60/'Raw Data Trent Ltd'!H$61 -> 0.12644883 | J27: ='Raw Data Trent Ltd'!I60/'Raw Data Trent Ltd'!I$61 -> 0.18724753 | ... L27: ='Raw Data Trent Ltd'!K60/'Raw Data Trent Ltd'!K$61 -> 0.1860967
B29: Total Assets | C29: ='Raw Data Trent Ltd'!B77/'Raw Data Trent Ltd'!B$77 -> 1 | D29: ='Raw Data Trent Ltd'!C77/'Raw Data Trent Ltd'!C$77 -> 1 | E29: ='Raw Data Trent Ltd'!D77/'Raw Data Trent Ltd'!D$77 -> 1 | F29: ='Raw Data Trent Ltd'!E77/'Raw Data Trent Ltd'!E$77 -> 1 | G29: ='Raw Data Trent Ltd'!F77/'Raw Data Trent Ltd'!F$77 -> 1 | H29: ='Raw Data Trent Ltd'!G77/'Raw Data Trent Ltd'!G$77 -> 1 | I29: ='Raw Data Trent Ltd'!H77/'Raw Data Trent Ltd'!H$77 -> 1 | J29: ='Raw Data Trent Ltd'!I77/'Raw Data Trent Ltd'!I$77 -> 1 | ... L29: ='Raw Data Trent Ltd'!K77/'Raw Data Trent Ltd'!K$77 -> 1
B30: ='Raw Data Trent Ltd'!A62 -> Net Block | C30: ='Raw Data Trent Ltd'!B62/'Raw Data Trent Ltd'!B$77 -> 0.24691641 | D30: ='Raw Data Trent Ltd'!C62/'Raw Data Trent Ltd'!C$77 -> 0.2622289 | E30: ='Raw Data Trent Ltd'!D62/'Raw Data Trent Ltd'!D$77 -> 0.25878941 | F30: ='Raw Data Trent Ltd'!E62/'Raw Data Trent Ltd'!E$77 -> 0.49729238 | G30: ='Raw Data Trent Ltd'!F62/'Raw Data Trent Ltd'!F$77 -> 0.5335367 | H30: ='Raw Data Trent Ltd'!G62/'Raw Data Trent Ltd'!G$77 -> 0.60661375 | I30: ='Raw Data Trent Ltd'!H62/'Raw Data Trent Ltd'!H$77 -> 0.56016002 | J30: ='Raw Data Trent Ltd'!I62/'Raw Data Trent Ltd'!I$77 -> 0.34208399 | ... L30: ='Raw Data Trent Ltd'!K62/'Raw Data Trent Ltd'!K$77 -> 0.47053778
B31: ='Raw Data Trent Ltd'!A63 -> Capital Work in Progress | C31: ='Raw Data Trent Ltd'!B63/'Raw Data Trent Ltd'!B$77 -> 0.0024659692 | D31: ='Raw Data Trent Ltd'!C63/'Raw Data Trent Ltd'!C$77 -> 0.0041055543 | E31: ='Raw Data Trent Ltd'!D63/'Raw Data Trent Ltd'!D$77 -> 0.034071191 | F31: ='Raw Data Trent Ltd'!E63/'Raw Data Trent Ltd'!E$77 -> 0.0042348566 | G31: ='Raw Data Trent Ltd'!F63/'Raw Data Trent Ltd'!F$77 -> 0.01886532 | H31: ='Raw Data Trent Ltd'!G63/'Raw Data Trent Ltd'!G$77 -> 0.013554197 | I31: ='Raw Data Trent Ltd'!H63/'Raw Data Trent Ltd'!H$77 -> 0.012586726 | J31: ='Raw Data Trent Ltd'!I63/'Raw Data Trent Ltd'!I$77 -> 0.031246553 | ... L31: ='Raw Data Trent Ltd'!K63/'Raw Data Trent Ltd'!K$77 -> 0.021655648
B32: ='Raw Data Trent Ltd'!A64 -> Investments | C32: ='Raw Data Trent Ltd'!B64/'Raw Data Trent Ltd'!B$77 -> 0.48597593 | D32: ='Raw Data Trent Ltd'!C64/'Raw Data Trent Ltd'!C$77 -> 0.43790296 | E32: ='Raw Data Trent Ltd'!D64/'Raw Data Trent Ltd'!D$77 -> 0.34502259 | F32: ='Raw Data Trent Ltd'!E64/'Raw Data Trent Ltd'!E$77 -> 0.27508045 | G32: ='Raw Data Trent Ltd'!F64/'Raw Data Trent Ltd'!F$77 -> 0.25984629 | H32: ='Raw Data Trent Ltd'!G64/'Raw Data Trent Ltd'!G$77 -> 0.16615541 | I32: ='Raw Data Trent Ltd'!H64/'Raw Data Trent Ltd'!H$77 -> 0.13733414 | J32: ='Raw Data Trent Ltd'!I64/'Raw Data Trent Ltd'!I$77 -> 0.19772123 | ... L32: ='Raw Data Trent Ltd'!K64/'Raw Data Trent Ltd'!K$77 -> 0.11807994
B33: ='Raw Data Trent Ltd'!A65 -> Other Assets | C33: ='Raw Data Trent Ltd'!B75/'Raw Data Trent Ltd'!B$77 -> 0.10914164 | D33: ='Raw Data Trent Ltd'!C75/'Raw Data Trent Ltd'!C$77 -> 0.1276532 | E33: ='Raw Data Trent Ltd'!D75/'Raw Data Trent Ltd'!D$77 -> 0.14022026 | F33: ='Raw Data Trent Ltd'!E75/'Raw Data Trent Ltd'!E$77 -> 0.098754603 | G33: ='Raw Data Trent Ltd'!F75/'Raw Data Trent Ltd'!F$77 -> 0.095044665 | H33: ='Raw Data Trent Ltd'!G75/'Raw Data Trent Ltd'!G$77 -> 0.087866715 | I33: ='Raw Data Trent Ltd'!H75/'Raw Data Trent Ltd'!H$77 -> 0.10655656 | J33: ='Raw Data Trent Ltd'!I75/'Raw Data Trent Ltd'!I$77 -> 0.15498866 | ... L33: ='Raw Data Trent Ltd'!K75/'Raw Data Trent Ltd'!K$77 -> 0.16607211
B34: ='Raw Data Trent Ltd'!A67 -> Receivables | C34: ='Raw Data Trent Ltd'!B67/'Raw Data Trent Ltd'!B$77 -> 0.0026639667 | D34: ='Raw Data Trent Ltd'!C67/'Raw Data Trent Ltd'!C$77 -> 0.0064644285 | E34: ='Raw Data Trent Ltd'!D67/'Raw Data Trent Ltd'!D$77 -> 0.0064640685 | F34: ='Raw Data Trent Ltd'!E67/'Raw Data Trent Ltd'!E$77 -> 0.0031089513 | G34: ='Raw Data Trent Ltd'!F67/'Raw Data Trent Ltd'!F$77 -> 0.0036287526 | H34: ='Raw Data Trent Ltd'!G67/'Raw Data Trent Ltd'!G$77 -> 0.002363442 | I34: ='Raw Data Trent Ltd'!H67/'Raw Data Trent Ltd'!H$77 -> 0.0042553823 | J34: ='Raw Data Trent Ltd'!I67/'Raw Data Trent Ltd'!I$77 -> 0.011413412 | ... L34: ='Raw Data Trent Ltd'!K67/'Raw Data Trent Ltd'!K$77 -> 0.0043602891
B35: ='Raw Data Trent Ltd'!A68 -> Inventory | C35: ='Raw Data Trent Ltd'!B68/'Raw Data Trent Ltd'!B$77 -> 0.13741028 | D35: ='Raw Data Trent Ltd'!C68/'Raw Data Trent Ltd'!C$77 -> 0.14759874 | E35: ='Raw Data Trent Ltd'!D68/'Raw Data Trent Ltd'!D$77 -> 0.19423862 | F35: ='Raw Data Trent Ltd'!E68/'Raw Data Trent Ltd'!E$77 -> 0.11037685 | G35: ='Raw Data Trent Ltd'!F68/'Raw Data Trent Ltd'!F$77 -> 0.074844551 | H35: ='Raw Data Trent Ltd'!G68/'Raw Data Trent Ltd'!G$77 -> 0.11231915 | I35: ='Raw Data Trent Ltd'!H68/'Raw Data Trent Ltd'!H$77 -> 0.1684285 | J35: ='Raw Data Trent Ltd'!I68/'Raw Data Trent Ltd'!I$77 -> 0.22099766 | ... L35: ='Raw Data Trent Ltd'!K68/'Raw Data Trent Ltd'!K$77 -> 0.19516514
B36: ='Raw Data Trent Ltd'!A69 -> Cash & Bank | C36: ='Raw Data Trent Ltd'!B69/'Raw Data Trent Ltd'!B$77 -> 0.015425807 | D36: ='Raw Data Trent Ltd'!C69/'Raw Data Trent Ltd'!C$77 -> 0.014046219 | E36: ='Raw Data Trent Ltd'!D69/'Raw Data Trent Ltd'!D$77 -> 0.02119386 | F36: ='Raw Data Trent Ltd'!E69/'Raw Data Trent Ltd'!E$77 -> 0.01115191 | G36: ='Raw Data Trent Ltd'!F69/'Raw Data Trent Ltd'!F$77 -> 0.014233725 | H36: ='Raw Data Trent Ltd'!G69/'Raw Data Trent Ltd'!G$77 -> 0.011127333 | I36: ='Raw Data Trent Ltd'!H69/'Raw Data Trent Ltd'!H$77 -> 0.010678671 | J36: ='Raw Data Trent Ltd'!I69/'Raw Data Trent Ltd'!I$77 -> 0.041548504 | ... L36: ='Raw Data Trent Ltd'!K69/'Raw Data Trent Ltd'!K$77 -> 0.024129093

Sheet Ratio Analysis Trent Ltd
B2: ="Ratio Analysis of - "&'Raw Data Trent Ltd'!B1 -> Ratio Analysis of - TRENT LTD
B3: Years | C3: ='Raw Data Trent Ltd'!B16 -> 42825 | D3: =C3+365 -> 43190 | E3: =D3+365 -> 43555 | F3: =E3+365 -> 43920 | G3: =F3+365 -> 44285 | H3: =G3+365 -> 44650 | I3: =H3+365 -> 45015 | J3: =I3+365 -> 45380 | K3: =J3+365 -> 45745 | L3: =K3+365 -> 46110 | M3: Trend | N3: Mean | O3: Median
B5: SalesGrowth | D5: =IFERROR('Historical IFS Trent Ltd'!D7,0) -> 0.19036216 | E5: =IFERROR('Historical IFS Trent Ltd'!E7,0) -> 0.21913732 | F5: =IFERROR('Historical IFS Trent Ltd'!F7,0) -> 0.32534674 | G5: =IFERROR('Historical IFS Trent Ltd'!G7,0) -> -0.25617473 | H5: =IFERROR('Historical IFS Trent Ltd'!H7,0) -> 0.73470474 | I5: =IFERROR('Historical IFS Trent Ltd'!I7,0) -> 0.83236624 | J5: =IFERROR('Historical IFS Trent Ltd'!J7,0) -> 0.50146566 | K5: =IFERROR('Historical IFS Trent Ltd'!K7,0) -> 0.38460264 | L5: =IFERROR('Historical IFS Trent Ltd'!L7,0) -> 0.1715592 | N5: =IFERROR(AVERAGE(D5:L5),0) -> 0.34481889 | O5: =IFERROR(MEDIAN(D5:L5),0) -> 0.32534674
B6: EBITDA Growth | D6: =IFERROR(('Historical IFS Trent Ltd'!D18/'Historical IFS Trent Ltd'!C18)-1,0) -> 0.56144687 | E6: =IFERROR(('Historical IFS Trent Ltd'!E18/'Historical IFS Trent Ltd'!D18)-1,0) -> 0.15414868 | F6: =IFERROR(('Historical IFS Trent Ltd'!F18/'Historical IFS Trent Ltd'!E18)-1,0) -> 1.1981799 | G6: =IFERROR(('Historical IFS Trent Ltd'!G18/'Historical IFS Trent Ltd'!F18)-1,0) -> -0.78473259 | H6: =IFERROR(('Historical IFS Trent Ltd'!H18/'Historical IFS Trent Ltd'!G18)-1,0) -> 4.2227979 | I6: =IFERROR(('Historical IFS Trent Ltd'!I18/'Historical IFS Trent Ltd'!H18)-1,0) -> 0.87340261 | J6: =IFERROR(('Historical IFS Trent Ltd'!J18/'Historical IFS Trent Ltd'!I18)-1,0) -> 0.76878338 | K6: =IFERROR(('Historical IFS Trent Ltd'!K18/'Historical IFS Trent Ltd'!J18)-1,0) -> 0.43095058 | L6: =IFERROR(('Historical IFS Trent Ltd'!L18/'Historical IFS Trent Ltd'!K18)-1,0) -> 0.30263904 | N6: =IFERROR(AVERAGE(D6:L6),0) -> 0.85862404 | O6: =IFERROR(MEDIAN(D6:L6),0) -> 0.56144687
B7: EBIT Growth | D7: =IFERROR(('Historical IFS Trent Ltd'!D27/'Historical IFS Trent Ltd'!C27)-1,0) -> 1.552795 | E7: =IFERROR(('Historical IFS Trent Ltd'!E27/'Historical IFS Trent Ltd'!D27)-1,0) -> 0.16058394 | F7: =IFERROR(('Historical IFS Trent Ltd'!F27/'Historical IFS Trent Ltd'!E27)-1,0) -> -0.86727391 | G7: =IFERROR(('Historical IFS Trent Ltd'!G27/'Historical IFS Trent Ltd'!F27)-1,0) -> -23.01634 | H7: =IFERROR(('Historical IFS Trent Ltd'!H27/'Historical IFS Trent Ltd'!G27)-1,0) -> -0.89871852 | I7: =IFERROR(('Historical IFS Trent Ltd'!I27/'Historical IFS Trent Ltd'!H27)-1,0) -> -6.1653639 | J7: =IFERROR(('Historical IFS Trent Ltd'!J27/'Historical IFS Trent Ltd'!I27)-1,0) -> 3.4068662 | K7: =IFERROR(('Historical IFS Trent Ltd'!K27/'Historical IFS Trent Ltd'!J27)-1,0) -> 0.85067388 | L7: =IFERROR(('Historical IFS Trent Ltd'!L27/'Historical IFS Trent Ltd'!K27)-1,0) -> 0.24304219 | N7: =IFERROR(AVERAGE(D7:L7),0) -> -2.7481928 | O7: =IFERROR(MEDIAN(D7:L7),0) -> 0.16058394
B8: Net Profit Growth | D8: =IFERROR(('Historical IFS Trent Ltd'!D33/'Historical IFS Trent Ltd'!C33)-1,0) -> 15.365385 | E8: =IFERROR(('Historical IFS Trent Ltd'!E33/'Historical IFS Trent Ltd'!D33)-1,0) -> 0.086452913 | F8: =IFERROR(('Historical IFS Trent Ltd'!F33/'Historical IFS Trent Ltd'!E33)-1,0) -> -1.6280902 | G8: =IFERROR(('Historical IFS Trent Ltd'!G33/'Historical IFS Trent Ltd'!F33)-1,0) -> 8.3611316 | H8: =IFERROR(('Historical IFS Trent Ltd'!H33/'Historical IFS Trent Ltd'!G33)-1,0) -> -0.69106247 | I8: =IFERROR(('Historical IFS Trent Ltd'!I33/'Historical IFS Trent Ltd'!H33)-1,0) -> -1.4510888 | J8: =IFERROR(('Historical IFS Trent Ltd'!J33/'Historical IFS Trent Ltd'!I33)-1,0) -> 8.2127098 | K8: =IFERROR(('Historical IFS Trent Ltd'!K33/'Historical IFS Trent Ltd'!J33)-1,0) -> 1.5163238 | L8: =IFERROR(('Historical IFS Trent Ltd'!L33/'Historical IFS Trent Ltd'!K33)-1,0) -> 0.32484646 | N8: =IFERROR(AVERAGE(D8:L8),0) -> 3.3440675 | O8: =IFERROR(MEDIAN(D8:L8),0) -> 0.32484646
B9: Dividend Growth | D9: =IFERROR(('Historical IFS Trent Ltd'!D41/'Historical IFS Trent Ltd'!C41)-1,0) -> 0.14986458 | E9: =IFERROR(('Historical IFS Trent Ltd'!E41/'Historical IFS Trent Ltd'!D41)-1,0) -> 0.13059409 | F9: =IFERROR(('Historical IFS Trent Ltd'!F41/'Historical IFS Trent Ltd'!E41)-1,0) -> -0.23078704 | G9: =IFERROR(('Historical IFS Trent Ltd'!G41/'Historical IFS Trent Ltd'!F41)-1,0) -> -0.4 | H9: =IFERROR(('Historical IFS Trent Ltd'!H41/'Historical IFS Trent Ltd'!G41)-1,0) -> 1.8335677 | I9: =IFERROR(('Historical IFS Trent Ltd'!I41/'Historical IFS Trent Ltd'!H41)-1,0) -> 0.29401059 | J9: =IFERROR(('Historical IFS Trent Ltd'!J41/'Historical IFS Trent Ltd'!I41)-1,0) -> 0.45454545 | K9: =IFERROR(('Historical IFS Trent Ltd'!K41/'Historical IFS Trent Ltd'!J41)-1,0) -> 0.5625 | L9: =IFERROR(('Historical IFS Trent Ltd'!L41/'Historical IFS Trent Ltd'!K41)-1,0) -> 0.2 | N9: =IFERROR(AVERAGE(D9:L9),0) -> 0.33269949 | O9: =IFERROR(MEDIAN(D9:L9),0) -> 0.2
B11: Gross Margin | C11: =IFERROR('Historical IFS Trent Ltd'!C13,0) -> 0.33279446 | D11: =IFERROR('Historical IFS Trent Ltd'!D13,0) -> 0.34735291 | E11: =IFERROR('Historical IFS Trent Ltd'!E13,0) -> 0.32264736 | F11: =IFERROR('Historical IFS Trent Ltd'!F13,0) -> 0.30954567 | G11: =IFERROR('Historical IFS Trent Ltd'!G13,0) -> 0.23685286 | H11: =IFERROR('Historical IFS Trent Ltd'!H13,0) -> 0.31447837 | I11: =IFERROR('Historical IFS Trent Ltd'!I13,0) -> 0.30416573 | J11: =IFERROR('Historical IFS Trent Ltd'!J13,0) -> 0.31359156 | ... L11: =IFERROR('Historical IFS Trent Ltd'!L13,0) -> 0.37132271 | N11: =IFERROR(AVERAGE(C11:L11),0) -> 0.31685026 | O11: =IFERROR(AVERAGE(D11:M11),0) -> 0.31507868
B12: EBITDA Margin | C12: =IFERROR('Historical IFS Trent Ltd'!C19,0) -> 0.073674163 | D12: =IFERROR('Historical IFS Trent Ltd'!D19,0) -> 0.096641421 | E12: =IFERROR('Historical IFS Trent Ltd'!E19,0) -> 0.09148975 | F12: =IFERROR('Historical IFS Trent Ltd'!F19,0) -> 0.15174212 | G12: =IFERROR('Historical IFS Trent Ltd'!G19,0) -> 0.043915062 | H12: =IFERROR('Historical IFS Trent Ltd'!H19,0) -> 0.13221818 | I12: =IFERROR('Historical IFS Trent Ltd'!I19,0) -> 0.13517924 | J12: =IFERROR('Historical IFS Trent Ltd'!J19,0) -> 0.15924626 | ... L12: =IFERROR('Historical IFS Trent Ltd'!L19,0) -> 0.18299051 | N12: =IFERROR(AVERAGE(C12:L12),0) -> 0.12316736 | O12: =IFERROR(AVERAGE(D12:M12),0) -> 0.1286666
B13: EBIT Margin | C13: =IFERROR(('Historical IFS Trent Ltd'!C27+'Historical IFS Trent Ltd'!C21)/'Historical IFS Trent Ltd'!C6,0) -> 0.050892719 | D13: =IFERROR(('Historical IFS Trent Ltd'!D27+'Historical IFS Trent Ltd'!D21)/'Historical IFS Trent Ltd'!D6,0) -> 0.075537901 | E13: =IFERROR(('Historical IFS Trent Ltd'!E27+'Historical IFS Trent Ltd'!E21)/'Historical IFS Trent Ltd'!E6,0) -> 0.071845155 | F13: =IFERROR(('Historical IFS Trent Ltd'!F27+'Historical IFS Trent Ltd'!F21)/'Historical IFS Trent Ltd'!F6,0) -> 0.08081802 | G13: =IFERROR(('Historical IFS Trent Ltd'!G27+'Historical IFS Trent Ltd'!G21)/'Historical IFS Trent Ltd'!G6,0) -> -0.055315161 | H13: =IFERROR(('Historical IFS Trent Ltd'!H27+'Historical IFS Trent Ltd'!H21)/'Historical IFS Trent Ltd'!H6,0) -> 0.06311666 | I13: =IFERROR(('Historical IFS Trent Ltd'!I27+'Historical IFS Trent Ltd'!I21)/'Historical IFS Trent Ltd'!I6,0) -> 0.075280089 | J13: =IFERROR(('Historical IFS Trent Ltd'!J27+'Historical IFS Trent Ltd'!J21)/'Historical IFS Trent Ltd'!J6,0) -> 0.10501563 | ... L13: =IFERROR(('Historical IFS Trent Ltd'!L27+'Historical IFS Trent Ltd'!L21)/'Historical IFS Trent Ltd'!L6,0) -> 0.11518261 | N13: =IFERROR(AVERAGE(C13:L13),0) -> 0.06947065 | O13: =IFERROR(AVERAGE(D13:M13),0) -> 0.071534865
B14: EBT Margin | C14: =IFERROR('Historical IFS Trent Ltd'!C28,0) -> 0.025760853 | D14: =IFERROR('Historical IFS Trent Ltd'!D28,0) -> 0.05524552 | E14: =IFERROR('Historical IFS Trent Ltd'!E28,0) -> 0.052592159 | F14: =IFERROR('Historical IFS Trent Ltd'!F28,0) -> 0.0052668116 | G14: =IFERROR('Historical IFS Trent Ltd'!G28,0) -> -0.15589134 | H14: =IFERROR('Historical IFS Trent Ltd'!H28,0) -> -0.0091017826 | I14: =IFERROR('Historical IFS Trent Ltd'!I28,0) -> 0.025657545 | J14: =IFERROR('Historical IFS Trent Ltd'!J28,0) -> 0.075305997 | ... L14: =IFERROR('Historical IFS Trent Ltd'!L28,0) -> 0.10679623 | N14: =IFERROR(AVERAGE(C14:L14),0) -> 0.028228676 | O14: =IFERROR(AVERAGE(D14:M14),0) -> 0.028502878
B15: Net Profit Margin | C15: =IFERROR('Historical IFS Trent Ltd'!C34,0) -> 0.0020083423 | D15: =IFERROR('Historical IFS Trent Ltd'!D34,0) -> 0.027611172 | E15: =IFERROR('Historical IFS Trent Ltd'!E34,0) -> 0.02460612 | F15: =IFERROR('Historical IFS Trent Ltd'!F34,0) -> -0.011660996 | G15: =IFERROR('Historical IFS Trent Ltd'!G34,0) -> -0.14675506 | H15: =IFERROR('Historical IFS Trent Ltd'!H34,0) -> -0.026135944 | I15: =IFERROR('Historical IFS Trent Ltd'!I34,0) -> 0.0064341023 | J15: =IFERROR('Historical IFS Trent Ltd'!J34,0) -> 0.039478437 | ... L15: =IFERROR('Historical IFS Trent Ltd'!L34,0) -> 0.081133952 | N15: =IFERROR(AVERAGE(C15:L15),0) -> 0.0068466725 | O15: =IFERROR(AVERAGE(D15:M15),0) -> 0.0073842647
B17: SalesExpenses%Sales | C17: =IFERROR('Historical IFS Trent Ltd'!C16,0) -> 0.2591203 | D17: =IFERROR('Historical IFS Trent Ltd'!D16,0) -> 0.25071148 | E17: =IFERROR('Historical IFS Trent Ltd'!E16,0) -> 0.23115761 | F17: =IFERROR('Historical IFS Trent Ltd'!F16,0) -> 0.15780354 | G17: =IFERROR('Historical IFS Trent Ltd'!G16,0) -> 0.1929378 | H17: =IFERROR('Historical IFS Trent Ltd'!H16,0) -> 0.18226019 | I17: =IFERROR('Historical IFS Trent Ltd'!I16,0) -> 0.16898649 | J17: =IFERROR('Historical IFS Trent Ltd'!J16,0) -> 0.15434529 | ... L17: =IFERROR('Historical IFS Trent Ltd'!L16,0) -> 0.18833219 | N17: =IFERROR(AVERAGE(C17:L17),0) -> 0.19368291 | O17: =IFERROR(AVERAGE(D17:M17),0) -> 0.18641208
B18: Depreciation%Sales | C18: =IFERROR('Historical IFS Trent Ltd'!C25,0) -> 0.022781444 | D18: =IFERROR('Historical IFS Trent Ltd'!D25,0) -> 0.02110352 | E18: =IFERROR('Historical IFS Trent Ltd'!E25,0) -> 0.019644595 | F18: =IFERROR('Historical IFS Trent Ltd'!F25,0) -> 0.070924102 | G18: =IFERROR('Historical IFS Trent Ltd'!G25,0) -> 0.099230223 | H18: =IFERROR('Historical IFS Trent Ltd'!H25,0) -> 0.069101516 | I18: =IFERROR('Historical IFS Trent Ltd'!I25,0) -> 0.059899151 | J18: =IFERROR('Historical IFS Trent Ltd'!J25,0) -> 0.054230629 | ... L18: =IFERROR('Historical IFS Trent Ltd'!L25,0) -> 0.067807899 | N18: =IFERROR(AVERAGE(C18:L18),0) -> 0.053696705 | O18: =IFERROR(AVERAGE(D18:M18),0) -> 0.057131734
B19: OperatingIncome%Sales | C19: =C13 -> 0.050892719 | D19: =D13 -> 0.075537901 | E19: =E13 -> 0.071845155 | F19: =F13 -> 0.08081802 | G19: =G13 -> -0.055315161 | H19: =H13 -> 0.06311666 | I19: =I13 -> 0.075280089 | J19: =J13 -> 0.10501563 | ... L19: =L13 -> 0.11518261 | N19: =IFERROR(AVERAGE(C19:L19),0) -> 0.06947065 | O19: =IFERROR(AVERAGE(D19:M19),0) -> 0.071534865
B21: Return on Capital Employed | C21: =IFERROR(('Historical IFS Trent Ltd'!C27+'Historical IFS Trent Ltd'!C21)/SUM('Historical IFS Trent Ltd'!C47:C49),0) -> 0.047560366 | D21: =IFERROR(('Historical IFS Trent Ltd'!D27+'Historical IFS Trent Ltd'!D21)/SUM('Historical IFS Trent Ltd'!D47:D49),0) -> 0.082026374 | E21: =IFERROR(('Historical IFS Trent Ltd'!E27+'Historical IFS Trent Ltd'!E21)/SUM('Historical IFS Trent Ltd'!E47:E49),0) -> 0.088276925 | F21: =IFERROR(('Historical IFS Trent Ltd'!F27+'Historical IFS Trent Ltd'!F21)/SUM('Historical IFS Trent Ltd'!F47:F49),0) -> 0.10482938 | G21: =IFERROR(('Historical IFS Trent Ltd'!G27+'Historical IFS Trent Ltd'!G21)/SUM('Historical IFS Trent Ltd'!G47:G49),0) -> -0.027181967 | H21: =IFERROR(('Historical IFS Trent Ltd'!H27+'Historical IFS Trent Ltd'!H21)/SUM('Historical IFS Trent Ltd'!H47:H49),0) -> 0.040045928 | I21: =IFERROR(('Historical IFS Trent Ltd'!I27+'Historical IFS Trent Ltd'!I21)/SUM('Historical IFS Trent Ltd'!I47:I49),0) -> 0.087888459 | J21: =IFERROR(('Historical IFS Trent Ltd'!J27+'Historical IFS Trent Ltd'!J21)/SUM('Historical IFS Trent Ltd'!J47:J49),0) -> 0.22326753 | ... L21: =IFERROR(('Historical IFS Trent Ltd'!L27+'Historical IFS Trent Ltd'!L21)/SUM('Historical IFS Trent Ltd'!L47:L49),0) -> 0.24221841 | N21: =IFERROR(AVERAGE(C21:L21),0) -> 0.11389376 | O21: =IFERROR(AVERAGE(D21:M21),0) -> 0.12126413
B22: Retained Earnings% | C22: =IFERROR('Historical IFS Trent Ltd'!C44,0) -> 0 | D22: =IFERROR('Historical IFS Trent Ltd'!D44,0) -> 0.35856975 | E22: =IFERROR('Historical IFS Trent Ltd'!E44,0) -> 0.33250927 | F22: =IFERROR('Historical IFS Trent Ltd'!F44,0) -> 0 | G22: =IFERROR('Historical IFS Trent Ltd'!G44,0) -> 0 | H22: =IFERROR('Historical IFS Trent Ltd'!H44,0) -> 0 | I22: =IFERROR('Historical IFS Trent Ltd'!I44,0) -> 0 | J22: =IFERROR('Historical IFS Trent Ltd'!J44,0) -> 0.76714768 | ... L22: =IFERROR('Historical IFS Trent Ltd'!L44,0) -> 0.86903666 | N22: =IFERROR(AVERAGE(C22:L22),0) -> 0.31826748 | O22: =IFERROR(AVERAGE(D22:M22),0) -> 0.35363053
B23: Return on Equity% | C23: =IFERROR('Historical IFS Trent Ltd'!C33/SUM('Historical IFS Trent Ltd'!C47:C48),0) -> 0.0023518922 | D23: =IFERROR('Historical IFS Trent Ltd'!D33/SUM('Historical IFS Trent Ltd'!D47:D48),0) -> 0.037339301 | E23: =IFERROR('Historical IFS Trent Ltd'!E33/SUM('Historical IFS Trent Ltd'!E47:E48),0) -> 0.039307383 | F23: =IFERROR('Historical IFS Trent Ltd'!F33/SUM('Historical IFS Trent Ltd'!F47:F48),0) -> -0.017024253 | G23: =IFERROR('Historical IFS Trent Ltd'!G33/SUM('Historical IFS Trent Ltd'!G47:G48),0) -> -0.16451581 | H23: =IFERROR('Historical IFS Trent Ltd'!H33/SUM('Historical IFS Trent Ltd'!H47:H48),0) -> -0.049729272 | I23: =IFERROR('Historical IFS Trent Ltd'!I33/SUM('Historical IFS Trent Ltd'!I47:I48),0) -> 0.020431595 | J23: =IFERROR('Historical IFS Trent Ltd'!J33/SUM('Historical IFS Trent Ltd'!J47:J48),0) -> 0.12010355 | ... L23: =IFERROR('Historical IFS Trent Ltd'!L33/SUM('Historical IFS Trent Ltd'!L47:L48),0) -> 0.23318176 | N23: =IFERROR(AVERAGE(C23:L23),0) -> 0.04465301 | O23: =IFERROR(AVERAGE(D23:M23),0) -> 0.049353134
B24: Self Sustained Growth Rate | C24: =IFERROR(C22*C23,0) -> 0 | D24: =IFERROR(D22*D23,0) -> 0.013388744 | E24: =IFERROR(E22*E23,0) -> 0.013070069 | F24: =IFERROR(F22*F23,0) -> 0 | G24: =IFERROR(G22*G23,0) -> 0 | H24: =IFERROR(H22*H23,0) -> 0 | I24: =IFERROR(I22*I23,0) -> 0 | J24: =IFERROR(J22*J23,0) -> 0.092137157 | ... L24: =IFERROR(L22*L23,0) -> 0.2026435 | N24: =IFERROR(AVERAGE(C24:L24),0) -> 0.051377884 | O24: =IFERROR(AVERAGE(D24:M24),0) -> 0.057086538
B25: Interest Coverage Ratio | C25: =IFERROR(('Historical IFS Trent Ltd'!C27+'Historical IFS Trent Ltd'!C21)/'Historical IFS Trent Ltd'!C21,0) -> 2.0250274 | D25: =IFERROR(('Historical IFS Trent Ltd'!D27+'Historical IFS Trent Ltd'!D21)/'Historical IFS Trent Ltd'!D21,0) -> 3.722476 | E25: =IFERROR(('Historical IFS Trent Ltd'!E27+'Historical IFS Trent Ltd'!E21)/'Historical IFS Trent Ltd'!E21,0) -> 3.7316351 | F25: =IFERROR(('Historical IFS Trent Ltd'!F27+'Historical IFS Trent Ltd'!F21)/'Historical IFS Trent Ltd'!F21,0) -> 1.0697118 | G25: =IFERROR(('Historical IFS Trent Ltd'!G27+'Historical IFS Trent Ltd'!G21)/'Historical IFS Trent Ltd'!G21,0) -> -0.54998274 | H25: =IFERROR(('Historical IFS Trent Ltd'!H27+'Historical IFS Trent Ltd'!H21)/'Historical IFS Trent Ltd'!H21,0) -> 0.87396872 | I25: =IFERROR(('Historical IFS Trent Ltd'!I27+'Historical IFS Trent Ltd'!I21)/'Historical IFS Trent Ltd'!I21,0) -> 1.5170542 | J25: =IFERROR(('Historical IFS Trent Ltd'!J27+'Historical IFS Trent Ltd'!J21)/'Historical IFS Trent Ltd'!J21,0) -> 3.5347332 | ... L25: =IFERROR(('Historical IFS Trent Ltd'!L27+'Historical IFS Trent Ltd'!L21)/'Historical IFS Trent Ltd'!L21,0) -> 13.734482 | N25: =IFERROR(AVERAGE(C25:L25),0) -> 3.9278196 | O25: =IFERROR(AVERAGE(D25:M25),0) -> 4.1392409
B27: Debtor Turnover Ratio | C27: =IFERROR('Historical IFS Trent Ltd'!C6/'Historical IFS Trent Ltd'!C59,0) -> 306.15541 | D27: =IFERROR('Historical IFS Trent Ltd'!D6/'Historical IFS Trent Ltd'!D59,0) -> 142.87815 | E27: =IFERROR('Historical IFS Trent Ltd'!E6/'Historical IFS Trent Ltd'!E59,0) -> 159.02297 | F27: =IFERROR('Historical IFS Trent Ltd'!F6/'Historical IFS Trent Ltd'!F59,0) -> 203.62033 | G27: =IFERROR('Historical IFS Trent Ltd'!G6/'Historical IFS Trent Ltd'!G59,0) -> 124.8416 | H27: =IFERROR('Historical IFS Trent Ltd'!H6/'Historical IFS Trent Ltd'!H59,0) -> 246.33187 | I27: =IFERROR('Historical IFS Trent Ltd'!I6/'Historical IFS Trent Ltd'!I59,0) -> 239.66327 | J27: =IFERROR('Historical IFS Trent Ltd'!J6/'Historical IFS Trent Ltd'!J59,0) -> 151.39601 | ... L27: =IFERROR('Historical IFS Trent Ltd'!L6/'Historical IFS Trent Ltd'!L59,0) -> 392.53442 | N27: =IFERROR(AVERAGE(C27:L27),0) -> 223.8638 | O27: =IFERROR(AVERAGE(D27:M27),0) -> 214.72029
B28: Creditor Turnover Ratio | C28: =IFERROR('Historical IFS Trent Ltd'!C6/'Historical IFS Trent Ltd'!C50,0) -> 6.4084577 | D28: =IFERROR('Historical IFS Trent Ltd'!D6/'Historical IFS Trent Ltd'!D50,0) -> 6.1807712 | E28: =IFERROR('Historical IFS Trent Ltd'!E6/'Historical IFS Trent Ltd'!E50,0) -> 6.2907847 | F28: =IFERROR('Historical IFS Trent Ltd'!F6/'Historical IFS Trent Ltd'!F50,0) -> 1.2365271 | G28: =IFERROR('Historical IFS Trent Ltd'!G6/'Historical IFS Trent Ltd'!G50,0) -> 5.7998971 | H28: =IFERROR('Historical IFS Trent Ltd'!H6/'Historical IFS Trent Ltd'!H50,0) -> 7.0650269 | I28: =IFERROR('Historical IFS Trent Ltd'!I6/'Historical IFS Trent Ltd'!I50,0) -> 8.065388 | J28: =IFERROR('Historical IFS Trent Ltd'!J6/'Historical IFS Trent Ltd'!J50,0) -> 9.2281323 | ... L28: =IFERROR('Historical IFS Trent Ltd'!L6/'Historical IFS Trent Ltd'!L50,0) -> 9.1971732 | N28: =IFERROR(AVERAGE(C28:L28),0) -> 6.943003 | O28: =IFERROR(AVERAGE(D28:M28),0) -> 7.0023969
B29: Inventory Turnover | C29: =IFERROR('Historical IFS Trent Ltd'!C6/'Historical IFS Trent Ltd'!C60,0) -> 5.9354205 | D29: =IFERROR('Historical IFS Trent Ltd'!D6/'Historical IFS Trent Ltd'!D60,0) -> 6.257679 | E29: =IFERROR('Historical IFS Trent Ltd'!E6/'Historical IFS Trent Ltd'!E60,0) -> 5.2921269 | F29: =IFERROR('Historical IFS Trent Ltd'!F6/'Historical IFS Trent Ltd'!F60,0) -> 5.735312 | G29: =IFERROR('Historical IFS Trent Ltd'!G6/'Historical IFS Trent Ltd'!G60,0) -> 6.0528024 | H29: =IFERROR('Historical IFS Trent Ltd'!H6/'Historical IFS Trent Ltd'!H60,0) -> 5.1833644 | I29: =IFERROR('Historical IFS Trent Ltd'!I6/'Historical IFS Trent Ltd'!I60,0) -> 6.0551441 | J29: =IFERROR('Historical IFS Trent Ltd'!J6/'Historical IFS Trent Ltd'!J60,0) -> 7.8188383 | ... L29: =IFERROR('Historical IFS Trent Ltd'!L6/'Historical IFS Trent Ltd'!L60,0) -> 8.7698219 | N29: =IFERROR(AVERAGE(C29:L29),0) -> 6.5479087 | O29: =IFERROR(AVERAGE(D29:M29),0) -> 6.615963
B30: Fixed Asset Turnover | C30: =IFERROR('Historical IFS Trent Ltd'!C6/'Historical IFS Trent Ltd'!C53,0) -> 3.3030927 | D30: =IFERROR('Historical IFS Trent Ltd'!D6/'Historical IFS Trent Ltd'!D53,0) -> 3.5222112 | E30: =IFERROR('Historical IFS Trent Ltd'!E6/'Historical IFS Trent Ltd'!E53,0) -> 3.9720922 | F30: =IFERROR('Historical IFS Trent Ltd'!F6/'Historical IFS Trent Ltd'!F53,0) -> 1.2729849 | G30: =IFERROR('Historical IFS Trent Ltd'!G6/'Historical IFS Trent Ltd'!G53,0) -> 0.84908737 | H30: =IFERROR('Historical IFS Trent Ltd'!H6/'Historical IFS Trent Ltd'!H53,0) -> 0.95973935 | I30: =IFERROR('Historical IFS Trent Ltd'!I6/'Historical IFS Trent Ltd'!I53,0) -> 1.8206563 | J30: =IFERROR('Historical IFS Trent Ltd'!J6/'Historical IFS Trent Ltd'!J53,0) -> 5.0512302 | ... L30: =IFERROR('Historical IFS Trent Ltd'!L6/'Historical IFS Trent Ltd'!L53,0) -> 3.6374625 | N30: =IFERROR(AVERAGE(C30:L30),0) -> 2.878754 | O30: =IFERROR(AVERAGE(D30:M30),0) -> 2.8316052
B31: Capital Turnover Ratio | C31: =IFERROR('Historical IFS Trent Ltd'!C6/SUM('Historical IFS Trent Ltd'!C47:C48),0) -> 1.1710614 | D31: =IFERROR('Historical IFS Trent Ltd'!D6/SUM('Historical IFS Trent Ltd'!D47:D48),0) -> 1.3523258 | E31: =IFERROR('Historical IFS Trent Ltd'!E6/SUM('Historical IFS Trent Ltd'!E47:E48),0) -> 1.5974637 | F31: =IFERROR('Historical IFS Trent Ltd'!F6/SUM('Historical IFS Trent Ltd'!F47:F48),0) -> 1.4599312 | G31: =IFERROR('Historical IFS Trent Ltd'!G6/SUM('Historical IFS Trent Ltd'!G47:G48),0) -> 1.1210231 | H31: =IFERROR('Historical IFS Trent Ltd'!H6/SUM('Historical IFS Trent Ltd'!H47:H48),0) -> 1.9027157 | I31: =IFERROR('Historical IFS Trent Ltd'!I6/SUM('Historical IFS Trent Ltd'!I47:I48),0) -> 3.175516 | J31: =IFERROR('Historical IFS Trent Ltd'!J6/SUM('Historical IFS Trent Ltd'!J47:J48),0) -> 3.0422569 | ... L31: =IFERROR('Historical IFS Trent Ltd'!L6/SUM('Historical IFS Trent Ltd'!L47:L48),0) -> 2.8740343 | N31: =IFERROR(AVERAGE(C31:L31),0) -> 2.0833535 | O31: =IFERROR(AVERAGE(D31:M31),0) -> 2.1847193
B33: Debtor Days | C33: =IFERROR(365/C27,0) -> 1.192205 | D33: =IFERROR(365/D27,0) -> 2.5546244 | E33: =IFERROR(365/E27,0) -> 2.2952658 | F33: =IFERROR(365/F27,0) -> 1.7925519 | G33: =IFERROR(365/G27,0) -> 2.923705 | H33: =IFERROR(365/H27,0) -> 1.4817409 | I33: =IFERROR(365/I27,0) -> 1.5229701 | J33: =IFERROR(365/J27,0) -> 2.4108957 | ... L33: =IFERROR(365/L27,0) -> 0.92985477 | N33: =IFERROR(AVERAGE(C33:L33),0) -> 1.8444769 | O33: =IFERROR(AVERAGE(D33:M33),0) -> 1.9169516
B34: Payable Days | C34: =IFERROR(365/C28,0) -> 56.955982 | D34: =IFERROR(365/D28,0) -> 59.054119 | E34: =IFERROR(365/E28,0) -> 58.021378 | F34: =IFERROR(365/F28,0) -> 295.18157 | G34: =IFERROR(365/G28,0) -> 62.932151 | H34: =IFERROR(365/H28,0) -> 51.662932 | I34: =IFERROR(365/I28,0) -> 45.255107 | J34: =IFERROR(365/J28,0) -> 39.552966 | ... L34: =IFERROR(365/L28,0) -> 39.686107 | N34: =IFERROR(AVERAGE(C34:L34),0) -> 74.495673 | O34: =IFERROR(AVERAGE(D34:M34),0) -> 76.444528
B35: Inventory Days | C35: =IFERROR(365/C29,0) -> 61.495222 | D35: =IFERROR(365/D29,0) -> 58.328335 | E35: =IFERROR(365/E29,0) -> 68.970379 | F35: =IFERROR(365/F29,0) -> 63.640827 | G35: =IFERROR(365/G29,0) -> 60.302646 | H35: =IFERROR(365/H29,0) -> 70.417584 | I35: =IFERROR(365/I29,0) -> 60.279325 | J35: =IFERROR(365/J29,0) -> 46.682126 | ... L35: =IFERROR(365/L29,0) -> 41.620001 | N35: =IFERROR(AVERAGE(C35:L35),0) -> 57.529993 | O35: =IFERROR(AVERAGE(D35:M35),0) -> 57.089412
B36: Cash Conversion Cycle | C36: =IFERROR(SUM(C33,C35)-C34,0) -> 5.7314449 | D36: =IFERROR(SUM(D33,D35)-D34,0) -> 1.8288404 | E36: =IFERROR(SUM(E33,E35)-E34,0) -> 13.244267 | F36: =IFERROR(SUM(F33,F35)-F34,0) -> -229.74819 | G36: =IFERROR(SUM(G33,G35)-G34,0) -> 0.29420045 | H36: =IFERROR(SUM(H33,H35)-H34,0) -> 20.236393 | I36: =IFERROR(SUM(I33,I35)-I34,0) -> 16.547187 | J36: =IFERROR(SUM(J33,J35)-J34,0) -> 9.5400566 | ... L36: =IFERROR(SUM(L33,L35)-L34,0) -> 2.8637491 | N36: =IFERROR(AVERAGE(C36:L36),0) -> -15.121203 | O36: =IFERROR(AVERAGE(D36:M36),0) -> -17.438164
B38: CFO/Sales | C38: =IFERROR('Historical IFS Trent Ltd'!C78/'Historical IFS Trent Ltd'!C6,0) -> 0.05738121 | D38: =IFERROR('Historical IFS Trent Ltd'!D78/'Historical IFS Trent Ltd'!D6,0) -> 0.036153625 | E38: =IFERROR('Historical IFS Trent Ltd'!E78/'Historical IFS Trent Ltd'!E6,0) -> 0.0079840623 | F38: =IFERROR('Historical IFS Trent Ltd'!F78/'Historical IFS Trent Ltd'!F6,0) -> 0.10355768 | G38: =IFERROR('Historical IFS Trent Ltd'!G78/'Historical IFS Trent Ltd'!G6,0) -> 0.109913 | H38: =IFERROR('Historical IFS Trent Ltd'!H78/'Historical IFS Trent Ltd'!H6,0) -> 0.012672242 | I38: =IFERROR('Historical IFS Trent Ltd'!I78/'Historical IFS Trent Ltd'!I6,0) -> 0.072191041 | J38: =IFERROR('Historical IFS Trent Ltd'!J78/'Historical IFS Trent Ltd'!J6,0) -> 0.10892832 | ... L38: =IFERROR('Historical IFS Trent Ltd'!L78/'Historical IFS Trent Ltd'!L6,0) -> 0.13290685 | N38: =IFERROR(AVERAGE(C38:L38),0) -> 0.073862633 | O38: =IFERROR(AVERAGE(D38:M38),0) -> 0.075693902
